Workbook

Sheet Summary
A1: Lucky Sevens 20 — PAR summary (5x3, 20 lines, wild reels 2-4, STAR free spins x3)
A2: Variants differ only in base-game reel strips; pay table, features and free-spin strips are identical.
A4: Metric | B4: 96% variant | C4: 94% variant | D4: 92% variant
A5: Final theoretical RTP (Excel, live) | B5: =PAR_96!P20 -> 0.96000504 | C5: =PAR_94!P20 -> 0.94000848 | D5: =PAR_92!P20 -> 0.91999534
A6: Python exact RTP (full cycle + DP) | B6: 0.96000504 | C6: 0.94000848 | D6: 0.91999534
A7: Excel – Python (uncapped theoretical) | B7: =PAR_96!P18 -> 0 | C7: =PAR_94!P18 -> 0 | D7: =PAR_92!P18 -> 0
A8: Base game RTP | B8: =PAR_96!P8 -> 0.68013757 | C8: =PAR_94!P8 -> 0.6554251 | D8: =PAR_92!P8 -> 0.63686071
A9: Free-spin feature RTP | B9: =PAR_96!P16 -> 0.27986747 | C9: =PAR_94!P16 -> 0.28458338 | D9: =PAR_92!P16 -> 0.28313463
A10: Trigger frequency (1 in) | B10: =1/PAR_96!P9 -> 120.57563 | C10: =1/PAR_94!P9 -> 118.57754 | D10: =1/PAR_92!P9 -> 119.18428
A11: Hit frequency | B11: 0.56092854 | C11: 0.55172334 | D11: 0.53107262
A12: Volatility index (90%) | B12: 7.5535278 | C12: 7.5805501 | D12: 7.5806091
A13: Simulated rounds | B13: 250000000 | C13: 250000000 | D13: 250000000
A14: Simulated RTP | B14: 0.95982215 | C14: 0.93947723 | D14: 0.9201198
A15: Simulated RTP 95% CI low | B15: 0.95925355 | C15: 0.93890699 | D15: 0.91954885
A16: Simulated RTP 95% CI high | B16: 0.96039075 | C16: 0.94004747 | D16: 0.92069076
A17: Base strip lengths | B17: 40 / 42 / 42 / 42 / 40 | C17: 40 / 42 / 42 / 41 / 40 | D17: 40 / 42 / 41 / 42 / 40
A18: Base cycle size | B18: 118540800 | C18: 115718400 | D18: 115718400
A21: Colour key: black = formula, blue = input, green = cross-tab link, purple italic = imported from Python.

Sheet Inputs
A1: Lucky Sevens 20 — game rules and pay table
A2: Blue = editable input. All PAR math on the PAR_xx tabs references these cells and the Strips tab.
A4: Parameter | B4: Value | D4: Rules
A5: Reels | B5: 5 | D5: WILD substitutes for all symbols except STAR; appears on reels 2-4 only; no pay of its own.
A6: Rows | B6: 3 | D6: Line wins pay left to right on adjacent reels, highest win per line only; line pays x line bet.
A7: Paylines (fixed) | B7: 20 | D7: STAR pays anywhere (x total bet); at most one STAR visible per reel (strip spacing >= 3).
A8: Total bet (credits = line bets) | B8: 20 | D8: 3+ STAR in base game awards 10 free spins on the free-spin reel set; all free-spin wins x3.
A9: Free spins awarded per 3+ STAR | B9: 10 | D9: 3+ STAR during free spins retriggers +10 spins, up to 50 spins per feature.
A10: Free-spin win multiplier | B10: 3 | D10: Round win (base spin + its feature) capped at 5,000x total bet; feature ends when cap is reached.
A11: Max free spins per feature | B11: 50
A12: Max win per round (x total bet) | B12: 5000
A14: Line pay table (x line bet)
A15: Symbol | B15: 2 OAK | C15: 3 OAK | D15: 4 OAK | E15: 5 OAK
A16: SEVEN | B16: 2 | C16: 50 | D16: 250 | E16: 1000
A17: BAR | B17: 0 | C17: 30 | D17: 120 | E17: 500
A18: BELL | B18: 0 | C18: 20 | D18: 80 | E18: 300
A19: MELON | B19: 0 | C19: 15 | D19: 50 | E19: 150
A20: PLUM | B20: 0 | C20: 10 | D20: 40 | E20: 125
A21: A | B21: 0 | C21: 5 | D21: 25 | E21: 100
A22: K | B22: 0 | C22: 5 | D22: 20 | E22: 80
A23: Q | B23: 0 | C23: 5 | D23: 15 | E23: 60
A24: J | B24: 0 | C24: 4 | D24: 10 | E24: 50
A25: 10 | B25: 0 | C25: 4 | D25: 10 | E25: 40
A27: STAR scatter pays (x total bet)
A28: STARs visible | B28: Pay x bet
A29: 0 | B29: 0
A30: 1 | B30: 0
A31: 2 | B31: 0
A32: 3 | B32: 2
A33: 4 | B33: 10
A34: 5 | B34: 100

Sheet Paylines
A1: Payline definitions (row index per reel: 0 = top, 1 = middle, 2 = bottom)
A3: Line | B3: Reel 1 | C3: Reel 2 | D3: Reel 3 | E3: Reel 4 | F3: Reel 5 | H3: Each payline reads exactly one cell per reel, so for every line the symbol on reel r is distributed as reel r's
A4: 1 | B4: 1 | C4: 1 | D4: 1 | E4: 1 | F4: 1 | H4: strip frequencies. The single-line probability table on the PAR tabs is therefore exact for all 20 lines.
A5: 2 | B5: 0 | C5: 0 | D5: 0 | E5: 0 | F5: 0
A6: 3 | B6: 2 | C6: 2 | D6: 2 | E6: 2 | F6: 2
A7: 4 | B7: 0 | C7: 1 | D7: 2 | E7: 1 | F7: 0
A8: 5 | B8: 2 | C8: 1 | D8: 0 | E8: 1 | F8: 2
A9: 6 | B9: 0 | C9: 0 | D9: 1 | E9: 2 | F9: 2
A10: 7 | B10: 2 | C10: 2 | D10: 1 | E10: 0 | F10: 0
A11: 8 | B11: 1 | C11: 0 | D11: 0 | E11: 0 | F11: 1
A12: 9 | B12: 1 | C12: 2 | D12: 2 | E12: 2 | F12: 1
A13: 10 | B13: 0 | C13: 1 | D13: 1 | E13: 1 | F13: 0
A14: 11 | B14: 2 | C14: 1 | D14: 1 | E14: 1 | F14: 2
A15: 12 | B15: 1 | C15: 0 | D15: 1 | E15: 2 | F15: 1
A16: 13 | B16: 1 | C16: 2 | D16: 1 | E16: 0 | F16: 1
... A23: 20 | B23: 0 | C23: 2 | D23: 2 | E23: 2 | F23: 0

Sheet Strips
A1: Reel strips (stop position = row - 2). Edit any symbol and every PAR tab recalculates.
A2: Stop | B2: Base96 R1 | C2: Base96 R2 | D2: Base96 R3 | E2: Base96 R4 | F2: Base96 R5 | H2: Base94 R1 | I2: Base94 R2 | J2: Base94 R3 | K2: Base94 R4 | L2: Base94 R5 | N2: Base92 R1 | O2: Base92 R2 | P2: Base92 R3 | Q2: Base92 R4 | R2: Base92 R5 | T2: Free R1 | U2: Free R2 | V2: Free R3 | W2: Free R4 | X2: Free R5
A3: 0 | B3: STAR | C3: STAR | D3: STAR | E3: STAR | F3: STAR | H3: STAR | I3: STAR | J3: STAR | K3: STAR | L3: STAR | N3: STAR | O3: STAR | P3: STAR | Q3: STAR | R3: STAR | T3: STAR | U3: STAR | V3: STAR | W3: STAR | X3: STAR
A4: 1 | B4: 10 | C4: WILD | D4: WILD | E4: WILD | F4: J | H4: 10 | I4: WILD | J4: WILD | K4: WILD | L4: 10 | N4: 10 | O4: WILD | P4: WILD | Q4: WILD | R4: 10 | T4: 10 | U4: WILD | V4: WILD | W4: WILD | X4: 10
A5: 2 | B5: Q | C5: J | D5: 10 | E5: 10 | F5: 10 | H5: Q | I5: 10 | J5: 10 | K5: Q | L5: Q | N5: J | O5: 10 | P5: 10 | Q5: 10 | R5: J | T5: K | U5: 10 | V5: 10 | W5: 10 | X5: K
A6: 3 | B6: J | C6: 10 | D6: Q | E6: K | F6: K | H6: J | I6: Q | J6: Q | K6: J | L6: J | N6: K | O6: Q | P6: Q | Q6: J | R6: A | T6: Q | U6: MELON | V6: MELON | W6: MELON | X6: Q
A7: 4 | B7: K | C7: A | D7: J | E7: Q | F7: Q | H7: K | I7: J | J7: J | K7: 10 | L7: K | N7: Q | O7: J | P7: J | Q7: A | R7: K | T7: J | U7: PLUM | V7: PLUM | W7: PLUM | X7: J
A8: 5 | B8: A | C8: K | D8: A | E8: J | F8: A | H8: A | I8: A | J8: A | K8: A | L8: A | N8: A | O8: A | P8: A | Q8: K | R8: Q | T8: BELL | U8: A | V8: A | W8: A | X8: BELL
A9: 6 | B9: MELON | C9: Q | D9: K | E9: MELON | F9: MELON | H9: MELON | I9: K | J9: K | K9: K | L9: MELON | N9: BELL | O9: K | P9: K | Q9: Q | R9: MELON | T9: MELON | U9: K | V9: K | W9: K | X9: MELON
A10: 7 | B10: PLUM | C10: MELON | D10: MELON | E10: PLUM | F10: PLUM | H10: PLUM | I10: MELON | J10: MELON | K10: MELON | L10: PLUM | N10: MELON | O10: MELON | P10: MELON | Q10: MELON | R10: PLUM | T10: PLUM | U10: Q | V10: Q | W10: Q | X10: PLUM
A11: 8 | B11: 10 | C11: PLUM | D11: PLUM | E11: A | F11: J | H11: 10 | I11: PLUM | J11: PLUM | K11: PLUM | L11: 10 | N11: PLUM | O11: PLUM | P11: PLUM | Q11: PLUM | R11: 10 | T11: A | U11: J | V11: J | W11: J | X11: A
A12: 9 | B12: BAR | C12: BAR | D12: WILD | E12: BAR | F12: 10 | H12: BAR | I12: BAR | J12: WILD | K12: SEVEN | L12: BAR | N12: 10 | O12: BAR | P12: BAR | Q12: SEVEN | R12: BAR | T12: SEVEN | U12: SEVEN | V12: SEVEN | W12: SEVEN | X12: SEVEN
A13: 10 | B13: Q | C13: WILD | D13: BAR | E13: WILD | F13: BAR | H13: Q | I13: WILD | J13: BAR | K13: BAR | L13: Q | N13: BAR | O13: WILD | P13: WILD | Q13: BAR | R13: J | T13: BAR | U13: BAR | V13: BAR | W13: BAR | X13: BAR
A14: 11 | B14: J | C14: J | D14: 10 | E14: 10 | F14: BELL | H14: J | I14: 10 | J14: 10 | K14: BELL | L14: J | N14: J | O14: 10 | P14: 10 | Q14: WILD | R14: BELL | T14: 10 | U14: WILD | V14: WILD | W14: WILD | X14: 10
... A36: 33 | B36: MELON | C36: BELL | D36: BELL | E36: BELL | F36: MELON | H36: MELON | I36: BELL | J36: BELL | K36: WILD | L36: MELON | N36: MELON | O36: BELL | P36: MELON | Q36: BELL | R36: MELON | T36: 10 | U36: 10 | V36: 10 | W36: 10 | X36: 10
A37: 34 | B37: PLUM | C37: MELON | D37: MELON | E37: MELON | F37: PLUM | H37: PLUM | I37: MELON | J37: MELON | K37: MELON | L37: PLUM | N37: PLUM | O37: MELON | P37: PLUM | Q37: MELON | R37: PLUM
A38: 35 | B38: A | C38: PLUM | D38: PLUM | E38: PLUM | F38: A | H38: A | I38: PLUM | J38: PLUM | K38: PLUM | L38: A | N38: A | O38: PLUM | P38: WILD | Q38: PLUM | R38: A
A39: 36 | B39: K | C39: WILD | D39: WILD | E39: WILD | F39: K | H39: K | I39: WILD | J39: WILD | K39: A | L39: K | N39: K | O39: WILD | P39: A | Q39: WILD | R39: K
A40: 37 | B40: Q | C40: A | D40: A | E40: A | F40: Q | H40: Q | I40: A | J40: A | K40: K | L40: Q | N40: Q | O40: A | P40: K | Q40: A | R40: Q
A41: 38 | B41: J | C41: K | D41: K | E41: K | F41: J | H41: J | I41: K | J41: K | K41: Q | L41: J | N41: J | O41: K | P41: Q | Q41: K | R41: J
A42: 39 | B42: 10 | C42: Q | D42: Q | E42: Q | F42: 10 | H42: 10 | I42: Q | J42: Q | K42: J | L42: 10 | N42: 10 | O42: Q | P42: J | Q42: Q | R42: 10
A43: 40 | C43: J | D43: J | E43: J | I43: J | J43: J | K43: 10 | O43: J | P43: 10 | Q43: J
A44: 41 | C44: 10 | D44: 10 | E44: 10 | I44: 10 | J44: 10 | O44: 10 | Q44: 10

Sheet PAR_96
A1: PAR sheet — Lucky Sevens 20, 96% variant
A2: Black = live formula; blue = input; green = link to another tab; purple italic = value imported from the Python full-cycle / simulation run (for comparison only).
A4: 1. Reel strip symbol counts (COUNTIF over the Strips tab) | O4: RTP SUMMARY (live)
A5: Symbol | B5: Base R1 | C5: Base R2 | D5: Base R3 | E5: Base R4 | F5: Base R5 | H5: FS R1 | I5: FS R2 | J5: FS R3 | K5: FS R4 | L5: FS R5 | O5: Component | P5: Excel (formula) | Q5: Python exact
A6: WILD | B6: =COUNTIF(Strips!$B$3:$B$62,$A6) -> 0 | C6: =COUNTIF(Strips!$C$3:$C$62,$A6) -> 5 | D6: =COUNTIF(Strips!$D$3:$D$62,$A6) -> 6 | E6: =COUNTIF(Strips!$E$3:$E$62,$A6) -> 5 | F6: =COUNTIF(Strips!$F$3:$F$62,$A6) -> 0 | H6: =COUNTIF(Strips!$T$3:$T$62,$A6) -> 0 | I6: =COUNTIF(Strips!$U$3:$U$62,$A6) -> 5 | J6: =COUNTIF(Strips!$V$3:$V$62,$A6) -> 5 | K6: =COUNTIF(Strips!$W$3:$W$62,$A6) -> 5 | L6: =COUNTIF(Strips!$X$3:$X$62,$A6) -> 0 | O6: Base game line RTP | P6: =G54 -> 0.65948888 | Q6: 0.65948888
A7: STAR | B7: =COUNTIF(Strips!$B$3:$B$62,$A7) -> 1 | C7: =COUNTIF(Strips!$C$3:$C$62,$A7) -> 2 | D7: =COUNTIF(Strips!$D$3:$D$62,$A7) -> 1 | E7: =COUNTIF(Strips!$E$3:$E$62,$A7) -> 2 | F7: =COUNTIF(Strips!$F$3:$F$62,$A7) -> 1 | H7: =COUNTIF(Strips!$T$3:$T$62,$A7) -> 1 | I7: =COUNTIF(Strips!$U$3:$U$62,$A7) -> 1 | J7: =COUNTIF(Strips!$V$3:$V$62,$A7) -> 1 | K7: =COUNTIF(Strips!$W$3:$W$62,$A7) -> 1 | L7: =COUNTIF(Strips!$X$3:$X$62,$A7) -> 1 | O7: Base game STAR scatter RTP | P7: =$E$102 -> 0.020648688 | Q7: 0.020648688
A8: SEVEN | B8: =COUNTIF(Strips!$B$3:$B$62,$A8) -> 1 | C8: =COUNTIF(Strips!$C$3:$C$62,$A8) -> 1 | D8: =COUNTIF(Strips!$D$3:$D$62,$A8) -> 1 | E8: =COUNTIF(Strips!$E$3:$E$62,$A8) -> 1 | F8: =COUNTIF(Strips!$F$3:$F$62,$A8) -> 1 | H8: =COUNTIF(Strips!$T$3:$T$62,$A8) -> 2 | I8: =COUNTIF(Strips!$U$3:$U$62,$A8) -> 2 | J8: =COUNTIF(Strips!$V$3:$V$62,$A8) -> 2 | K8: =COUNTIF(Strips!$W$3:$W$62,$A8) -> 2 | L8: =COUNTIF(Strips!$X$3:$X$62,$A8) -> 2 | O8: Base game RTP | P8: =P6+P7 -> 0.68013757
A9: BAR | B9: =COUNTIF(Strips!$B$3:$B$62,$A9) -> 2 | C9: =COUNTIF(Strips!$C$3:$C$62,$A9) -> 2 | D9: =COUNTIF(Strips!$D$3:$D$62,$A9) -> 2 | E9: =COUNTIF(Strips!$E$3:$E$62,$A9) -> 2 | F9: =COUNTIF(Strips!$F$3:$F$62,$A9) -> 2 | H9: =COUNTIF(Strips!$T$3:$T$62,$A9) -> 2 | I9: =COUNTIF(Strips!$U$3:$U$62,$A9) -> 2 | J9: =COUNTIF(Strips!$V$3:$V$62,$A9) -> 2 | K9: =COUNTIF(Strips!$W$3:$W$62,$A9) -> 2 | L9: =COUNTIF(Strips!$X$3:$X$62,$A9) -> 2 | O9: P(trigger) per base spin | P9: =$E$103 -> 0.0082935496 | Q9: 0.0082935496
A10: BELL | B10: =COUNTIF(Strips!$B$3:$B$62,$A10) -> 2 | C10: =COUNTIF(Strips!$C$3:$C$62,$A10) -> 2 | D10: =COUNTIF(Strips!$D$3:$D$62,$A10) -> 2 | E10: =COUNTIF(Strips!$E$3:$E$62,$A10) -> 2 | F10: =COUNTIF(Strips!$F$3:$F$62,$A10) -> 2 | H10: =COUNTIF(Strips!$T$3:$T$62,$A10) -> 3 | I10: =COUNTIF(Strips!$U$3:$U$62,$A10) -> 2 | J10: =COUNTIF(Strips!$V$3:$V$62,$A10) -> 2 | K10: =COUNTIF(Strips!$W$3:$W$62,$A10) -> 2 | L10: =COUNTIF(Strips!$X$3:$X$62,$A10) -> 3 | O10: Free-spin line RTP per spin (raw) | P10: =G90 -> 1.0427217 | Q10: 1.0427217
A11: MELON | B11: =COUNTIF(Strips!$B$3:$B$62,$A11) -> 3 | C11: =COUNTIF(Strips!$C$3:$C$62,$A11) -> 3 | D11: =COUNTIF(Strips!$D$3:$D$62,$A11) -> 3 | E11: =COUNTIF(Strips!$E$3:$E$62,$A11) -> 3 | F11: =COUNTIF(Strips!$F$3:$F$62,$A11) -> 3 | H11: =COUNTIF(Strips!$T$3:$T$62,$A11) -> 3 | I11: =COUNTIF(Strips!$U$3:$U$62,$A11) -> 3 | J11: =COUNTIF(Strips!$V$3:$V$62,$A11) -> 3 | K11: =COUNTIF(Strips!$W$3:$W$62,$A11) -> 3 | L11: =COUNTIF(Strips!$X$3:$X$62,$A11) -> 3 | O11: Free-spin scatter RTP per spin (raw) | P11: =$E$115 -> 0.014719572 | Q11: 0.014719572
A12: PLUM | B12: =COUNTIF(Strips!$B$3:$B$62,$A12) -> 3 | C12: =COUNTIF(Strips!$C$3:$C$62,$A12) -> 3 | D12: =COUNTIF(Strips!$D$3:$D$62,$A12) -> 3 | E12: =COUNTIF(Strips!$E$3:$E$62,$A12) -> 3 | F12: =COUNTIF(Strips!$F$3:$F$62,$A12) -> 3 | H12: =COUNTIF(Strips!$T$3:$T$62,$A12) -> 3 | I12: =COUNTIF(Strips!$U$3:$U$62,$A12) -> 3 | J12: =COUNTIF(Strips!$V$3:$V$62,$A12) -> 3 | K12: =COUNTIF(Strips!$W$3:$W$62,$A12) -> 3 | L12: =COUNTIF(Strips!$X$3:$X$62,$A12) -> 3 | O12: P(retrigger) per free spin | P12: =$E$116 -> 0.0059924168 | Q12: 0.0059924168
A13: A | B13: =COUNTIF(Strips!$B$3:$B$62,$A13) -> 4 | C13: =COUNTIF(Strips!$C$3:$C$62,$A13) -> 4 | D13: =COUNTIF(Strips!$D$3:$D$62,$A13) -> 4 | E13: =COUNTIF(Strips!$E$3:$E$62,$A13) -> 3 | F13: =COUNTIF(Strips!$F$3:$F$62,$A13) -> 4 | H13: =COUNTIF(Strips!$T$3:$T$62,$A13) -> 3 | I13: =COUNTIF(Strips!$U$3:$U$62,$A13) -> 3 | J13: =COUNTIF(Strips!$V$3:$V$62,$A13) -> 3 | K13: =COUNTIF(Strips!$W$3:$W$62,$A13) -> 3 | L13: =COUNTIF(Strips!$X$3:$X$62,$A13) -> 3 | O13: Free-spin multiplier | P13: =Inputs!$B$10 -> 3
A14: K | B14: =COUNTIF(Strips!$B$3:$B$62,$A14) -> 5 | C14: =COUNTIF(Strips!$C$3:$C$62,$A14) -> 4 | D14: =COUNTIF(Strips!$D$3:$D$62,$A14) -> 4 | E14: =COUNTIF(Strips!$E$3:$E$62,$A14) -> 5 | F14: =COUNTIF(Strips!$F$3:$F$62,$A14) -> 5 | H14: =COUNTIF(Strips!$T$3:$T$62,$A14) -> 4 | I14: =COUNTIF(Strips!$U$3:$U$62,$A14) -> 3 | J14: =COUNTIF(Strips!$V$3:$V$62,$A14) -> 3 | K14: =COUNTIF(Strips!$W$3:$W$62,$A14) -> 3 | L14: =COUNTIF(Strips!$X$3:$X$62,$A14) -> 4 | O14: E[free spins per feature] | P14: =$G$172 -> 10.637375 | Q14: 10.637375
A15: Q | B15: =COUNTIF(Strips!$B$3:$B$62,$A15) -> 6 | C15: =COUNTIF(Strips!$C$3:$C$62,$A15) -> 4 | D15: =COUNTIF(Strips!$D$3:$D$62,$A15) -> 5 | E15: =COUNTIF(Strips!$E$3:$E$62,$A15) -> 5 | F15: =COUNTIF(Strips!$F$3:$F$62,$A15) -> 5 | H15: =COUNTIF(Strips!$T$3:$T$62,$A15) -> 4 | I15: =COUNTIF(Strips!$U$3:$U$62,$A15) -> 3 | J15: =COUNTIF(Strips!$V$3:$V$62,$A15) -> 3 | K15: =COUNTIF(Strips!$W$3:$W$62,$A15) -> 3 | L15: =COUNTIF(Strips!$X$3:$X$62,$A15) -> 4 | O15: Feature value (x total bet) | P15: =P14*P13*(P10+P11) -> 33.745197 | Q15: 33.745197
A16: J | B16: =COUNTIF(Strips!$B$3:$B$62,$A16) -> 6 | C16: =COUNTIF(Strips!$C$3:$C$62,$A16) -> 6 | D16: =COUNTIF(Strips!$D$3:$D$62,$A16) -> 5 | E16: =COUNTIF(Strips!$E$3:$E$62,$A16) -> 5 | F16: =COUNTIF(Strips!$F$3:$F$62,$A16) -> 7 | H16: =COUNTIF(Strips!$T$3:$T$62,$A16) -> 4 | I16: =COUNTIF(Strips!$U$3:$U$62,$A16) -> 3 | J16: =COUNTIF(Strips!$V$3:$V$62,$A16) -> 3 | K16: =COUNTIF(Strips!$W$3:$W$62,$A16) -> 3 | L16: =COUNTIF(Strips!$X$3:$X$62,$A16) -> 4 | O16: Free-spin feature RTP | P16: =P9*P15 -> 0.27986747 | Q16: 0.27986747
A17: 10 | B17: =COUNTIF(Strips!$B$3:$B$62,$A17) -> 7 | C17: =COUNTIF(Strips!$C$3:$C$62,$A17) -> 6 | D17: =COUNTIF(Strips!$D$3:$D$62,$A17) -> 6 | E17: =COUNTIF(Strips!$E$3:$E$62,$A17) -> 6 | F17: =COUNTIF(Strips!$F$3:$F$62,$A17) -> 7 | H17: =COUNTIF(Strips!$T$3:$T$62,$A17) -> 5 | I17: =COUNTIF(Strips!$U$3:$U$62,$A17) -> 4 | J17: =COUNTIF(Strips!$V$3:$V$62,$A17) -> 4 | K17: =COUNTIF(Strips!$W$3:$W$62,$A17) -> 4 | L17: =COUNTIF(Strips!$X$3:$X$62,$A17) -> 5 | O17: THEORETICAL RTP before 5,000x cap | P17: =P8+P16 -> 0.96000504 | Q17: 0.96000504
A18: Strip length | B18: =SUM(B6:B17) -> 40 | C18: =SUM(C6:C17) -> 42 | D18: =SUM(D6:D17) -> 42 | E18: =SUM(E6:E17) -> 42 | F18: =SUM(F6:F17) -> 40 | H18: =SUM(H6:H17) -> 34 | I18: =SUM(I6:I17) -> 34 | J18: =SUM(J6:J17) -> 34 | K18: =SUM(K6:K17) -> 34 | L18: =SUM(L6:L17) -> 34 | O18: Excel minus Python (uncapped) | P18: =P17-Q17 -> 0
A19: Full cycle (all stop combos) | B19: =PRODUCT(B18:F18) -> 118540800 | H19: =PRODUCT(H18:L18) -> 45435424 | O19: Max-win cap adjustment (exact DP, Python) | P19: -5.9554716e-44
O20: FINAL THEORETICAL RTP | P20: =P17+P19 -> 0.96000504 | Q20: 0.96000504
A21: 2. Base game line wins (exact, from strip counts) | O21: Hold (house edge) | P21: =1-P20 -> 0.039994962
A22: Symbol | B22: OAK | C22: Pay x line | D22: Combos (per line, full cycle) | E22: Prob per line | F22: 1 in | G22: RTP contribution
A23: SEVEN | B23: 2 | C23: =INDEX(Inputs!$B$16:$E$16,1,1) -> 2 | D23: =$B$8*($C$8+$C$6)*($D$18-($D$8+$D$6))*$E$18*$F$18 -> 352800 | E23: =D23/$B$19 -> 0.0029761905 | F23: =IF(E23>0,1/E23,"-") -> 336 | G23: =C23*E23 -> 0.005952381
A24: SEVEN | B24: 3 | C24: =INDEX(Inputs!$B$16:$E$16,1,2) -> 50 | D24: =$B$8*($C$8+$C$6)*($D$8+$D$6)*($E$18-($E$8+$E$6))*$F$18 -> 60480 | E24: =D24/$B$19 -> 0.00051020408 | F24: =IF(E24>0,1/E24,"-") -> 1960 | G24: =C24*E24 -> 0.025510204 | O24: RTP BY SYMBOL / FEATURE (live)
A25: SEVEN | B25: 4 | C25: =INDEX(Inputs!$B$16:$E$16,1,3) -> 250 | D25: =$B$8*($C$8+$C$6)*($D$8+$D$6)*($E$8+$E$6)*($F$18-($F$8+$F$6)) -> 9828 | E25: =D25/$B$19 -> 8.2908163e-05 | F25: =IF(E25>0,1/E25,"-") -> 12061.538 | G25: =C25*E25 -> 0.020727041 | O25: Source | P25: Base game | Q25: Free spins | R25: Total | S25: Share of RTP
A26: SEVEN | B26: 5 | C26: =INDEX(Inputs!$B$16:$E$16,1,4) -> 1000 | D26: =$B$8*($C$8+$C$6)*($D$8+$D$6)*($E$8+$E$6)*($F$8+$F$6) -> 252 | E26: =D26/$B$19 -> 2.1258503e-06 | F26: =IF(E26>0,1/E26,"-") -> 470400 | G26: =C26*E26 -> 0.0021258503 | O26: SEVEN lines | P26: =SUMIF($A$23:$A$53,"SEVEN",$G$23:$G$53) -> 0.054315476 | Q26: =P9*P14*P13*SUMIF($A$59:$A$89,"SEVEN",$G$59:$G$89) -> 0.071253119 | R26: =P26+Q26 -> 0.12556859 | S26: =R26/P20 -> 0.13079993
A27: BAR | B27: 3 | C27: =INDEX(Inputs!$B$17:$E$17,1,2) -> 30 | D27: =$B$9*($C$9+$C$6)*($D$9+$D$6)*($E$18-($E$9+$E$6))*$F$18 -> 156800 | E27: =D27/$B$19 -> 0.0013227513 | F27: =IF(E27>0,1/E27,"-") -> 756 | G27: =C27*E27 -> 0.03968254 | O27: BAR lines | P27: =SUMIF($A$23:$A$53,"BAR",$G$23:$G$53) -> 0.076455026 | Q27: =P9*P14*P13*SUMIF($A$59:$A$89,"BAR",$G$59:$G$89) -> 0.035062063 | R27: =P27+Q27 -> 0.11151709 | S27: =R27/P20 -> 0.11616303
A28: BAR | B28: 4 | C28: =INDEX(Inputs!$B$17:$E$17,1,3) -> 120 | D28: =$B$9*($C$9+$C$6)*($D$9+$D$6)*($E$9+$E$6)*($F$18-($F$9+$F$6)) -> 29792 | E28: =D28/$B$19 -> 0.00025132275 | F28: =IF(E28>0,1/E28,"-") -> 3978.9474 | G28: =C28*E28 -> 0.03015873 | O28: BELL lines | P28: =SUMIF($A$23:$A$53,"BELL",$G$23:$G$53) -> 0.050529101 | Q28: =P9*P14*P13*SUMIF($A$59:$A$89,"BELL",$G$59:$G$89) -> 0.035981143 | R28: =P28+Q28 -> 0.086510244 | S28: =R28/P20 -> 0.090114364
A29: BAR | B29: 5 | C29: =INDEX(Inputs!$B$17:$E$17,1,4) -> 500 | D29: =$B$9*($C$9+$C$6)*($D$9+$D$6)*($E$9+$E$6)*($F$9+$F$6) -> 1568 | E29: =D29/$B$19 -> 1.3227513e-05 | F29: =IF(E29>0,1/E29,"-") -> 75600 | G29: =C29*E29 -> 0.0066137566 | O29: MELON lines | P29: =SUMIF($A$23:$A$53,"MELON",$G$23:$G$53) -> 0.070699708 | Q29: =P9*P14*P13*SUMIF($A$59:$A$89,"MELON",$G$59:$G$89) -> 0.03272481 | R29: =P29+Q29 -> 0.10342452 | S29: =R29/P20 -> 0.10773331
A30: BELL | B30: 3 | C30: =INDEX(Inputs!$B$18:$E$18,1,2) -> 20 | D30: =$B$10*($C$10+$C$6)*($D$10+$D$6)*($E$18-($E$10+$E$6))*$F$18 -> 156800 | E30: =D30/$B$19 -> 0.0013227513 | F30: =IF(E30>0,1/E30,"-") -> 756 | G30: =C30*E30 -> 0.026455026 | O30: PLUM lines | P30: =SUMIF($A$23:$A$53,"PLUM",$G$23:$G$53) -> 0.051822157 | Q30: =P9*P14*P13*SUMIF($A$59:$A$89,"PLUM",$G$59:$G$89) -> 0.0243367 | R30: =P30+Q30 -> 0.076158858 | S30: =R30/P20 -> 0.079331727
A31: BELL | B31: 4 | C31: =INDEX(Inputs!$B$18:$E$18,1,3) -> 80 | D31: =$B$10*($C$10+$C$6)*($D$10+$D$6)*($E$10+$E$6)*($F$18-($F$10+$F$6)) -> 29792 | E31: =D31/$B$19 -> 0.00025132275 | F31: =IF(E31>0,1/E31,"-") -> 3978.9474 | G31: =C31*E31 -> 0.02010582 | O31: A lines | P31: =SUMIF($A$23:$A$53,"A",$G$23:$G$53) -> 0.05223518 | Q31: =P9*P14*P13*SUMIF($A$59:$A$89,"A",$G$59:$G$89) -> 0.014561757 | R31: =P31+Q31 -> 0.066796937 | S31: =R31/P20 -> 0.069579778
A32: BELL | B32: 5 | C32: =INDEX(Inputs!$B$18:$E$18,1,4) -> 300 | D32: =$B$10*($C$10+$C$6)*($D$10+$D$6)*($E$10+$E$6)*($F$10+$F$6) -> 1568 | E32: =D32/$B$19 -> 1.3227513e-05 | F32: =IF(E32>0,1/E32,"-") -> 75600 | G32: =C32*E32 -> 0.003968254 | O32: K lines | P32: =SUMIF($A$23:$A$53,"K",$G$23:$G$53) -> 0.066053207 | Q32: =P9*P14*P13*SUMIF($A$59:$A$89,"K",$G$59:$G$89) -> 0.017566564 | R32: =P32+Q32 -> 0.083619771 | S32: =R32/P20 -> 0.087103471
A33: MELON | B33: 3 | C33: =INDEX(Inputs!$B$19:$E$19,1,2) -> 15 | D33: =$B$11*($C$11+$C$6)*($D$11+$D$6)*($E$18-($E$11+$E$6))*$F$18 -> 293760 | E33: =D33/$B$19 -> 0.0024781341 | F33: =IF(E33>0,1/E33,"-") -> 403.52941 | G33: =C33*E33 -> 0.037172012 | O33: Q lines | P33: =SUMIF($A$23:$A$53,"Q",$G$23:$G$53) -> 0.073410168 | Q33: =P9*P14*P13*SUMIF($A$59:$A$89,"Q",$G$59:$G$89) -> 0.014822721 | R33: =P33+Q33 -> 0.088232888 | S33: =R33/P20 -> 0.091908776
A34: MELON | B34: 4 | C34: =INDEX(Inputs!$B$19:$E$19,1,3) -> 50 | D34: =$B$11*($C$11+$C$6)*($D$11+$D$6)*($E$11+$E$6)*($F$18-($F$11+$F$6)) -> 63936 | E34: =D34/$B$19 -> 0.0005393586 | F34: =IF(E34>0,1/E34,"-") -> 1854.0541 | G34: =C34*E34 -> 0.02696793 | O34: J lines | P34: =SUMIF($A$23:$A$53,"J",$G$23:$G$53) -> 0.073003725 | Q34: =P9*P14*P13*SUMIF($A$59:$A$89,"J",$G$59:$G$89) -> 0.011237829 | R34: =P34+Q34 -> 0.084241555 | S34: =R34/P20 -> 0.087751159
A35: MELON | B35: 5 | C35: =INDEX(Inputs!$B$19:$E$19,1,4) -> 150 | D35: =$B$11*($C$11+$C$6)*($D$11+$D$6)*($E$11+$E$6)*($F$11+$F$6) -> 5184 | E35: =D35/$B$19 -> 4.3731778e-05 | F35: =IF(E35>0,1/E35,"-") -> 22866.667 | G35: =C35*E35 -> 0.0065597668 | O35: 10 lines | P35: =SUMIF($A$23:$A$53,"10",$G$23:$G$53) -> 0.090965136 | Q35: =P9*P14*P13*SUMIF($A$59:$A$89,"10",$G$59:$G$89) -> 0.018425006 | R35: =P35+Q35 -> 0.10939014 | S35: =R35/P20 -> 0.11394747
A36: PLUM | B36: 3 | C36: =INDEX(Inputs!$B$20:$E$20,1,2) -> 10 | D36: =$B$12*($C$12+$C$6)*($D$12+$D$6)*($E$18-($E$12+$E$6))*$F$18 -> 293760 | E36: =D36/$B$19 -> 0.0024781341 | F36: =IF(E36>0,1/E36,"-") -> 403.52941 | G36: =C36*E36 -> 0.024781341 | O36: STAR scatter pays | P36: =$E$102 -> 0.020648688 | Q36: =P9*P14*P13*$E$115 -> 0.0038957524 | R36: =P36+Q36 -> 0.02454444 | S36: =R36/P20 -> 0.025566991
A37: PLUM | B37: 4 | C37: =INDEX(Inputs!$B$20:$E$20,1,3) -> 40 | D37: =$B$12*($C$12+$C$6)*($D$12+$D$6)*($E$12+$E$6)*($F$18-($F$12+$F$6)) -> 63936 | E37: =D37/$B$19 -> 0.0005393586 | F37: =IF(E37>0,1/E37,"-") -> 1854.0541 | G37: =C37*E37 -> 0.021574344 | O37: Max-win cap | R37: =P19 -> -5.9554716e-44
A38: PLUM | B38: 5 | C38: =INDEX(Inputs!$B$20:$E$20,1,4) -> 125 | D38: =$B$12*($C$12+$C$6)*($D$12+$D$6)*($E$12+$E$6)*($F$12+$F$6) -> 5184 | E38: =D38/$B$19 -> 4.3731778e-05 | F38: =IF(E38>0,1/E38,"-") -> 22866.667 | G38: =C38*E38 -> 0.0054664723 | O38: Total | P38: =SUM(P26:P36) -> 0.68013757 | Q38: =SUM(Q26:Q36) -> 0.27986747 | R38: =SUM(R26:R37) -> 0.96000504
A39: A | B39: 3 | C39: =INDEX(Inputs!$B$21:$E$21,1,2) -> 5 | D39: =$B$13*($C$13+$C$6)*($D$13+$D$6)*($E$18-($E$13+$E$6))*$F$18 -> 489600 | E39: =D39/$B$19 -> 0.0041302235 | F39: =IF(E39>0,1/E39,"-") -> 242.11765 | G39: =C39*E39 -> 0.020651118 | O39: Check vs final RTP | R39: =R38-P20 -> 0
A40: A | B40: 4 | C40: =INDEX(Inputs!$B$21:$E$21,1,3) -> 25 | D40: =$B$13*($C$13+$C$6)*($D$13+$D$6)*($E$13+$E$6)*($F$18-($F$13+$F$6)) -> 103680 | E40: =D40/$B$19 -> 0.00087463557 | F40: =IF(E40>0,1/E40,"-") -> 1143.3333 | G40: =C40*E40 -> 0.021865889
A41: A | B41: 5 | C41: =INDEX(Inputs!$B$21:$E$21,1,4) -> 100 | D41: =$B$13*($C$13+$C$6)*($D$13+$D$6)*($E$13+$E$6)*($F$13+$F$6) -> 11520 | E41: =D41/$B$19 -> 9.718173e-05 | F41: =IF(E41>0,1/E41,"-") -> 10290 | G41: =C41*E41 -> 0.009718173
...

Sheet PAR_94
A1: PAR sheet — Lucky Sevens 20, 94% variant
A2: Black = live formula; blue = input; green = link to another tab; purple italic = value imported from the Python full-cycle / simulation run (for comparison only).
A4: 1. Reel strip symbol counts (COUNTIF over the Strips tab) | O4: RTP SUMMARY (live)
A5: Symbol | B5: Base R1 | C5: Base R2 | D5: Base R3 | E5: Base R4 | F5: Base R5 | H5: FS R1 | I5: FS R2 | J5: FS R3 | K5: FS R4 | L5: FS R5 | O5: Component | P5: Excel (formula) | Q5: Python exact
A6: WILD | B6: =COUNTIF(Strips!$H$3:$H$62,$A6) -> 0 | C6: =COUNTIF(Strips!$I$3:$I$62,$A6) -> 5 | D6: =COUNTIF(Strips!$J$3:$J$62,$A6) -> 6 | E6: =COUNTIF(Strips!$K$3:$K$62,$A6) -> 4 | F6: =COUNTIF(Strips!$L$3:$L$62,$A6) -> 0 | H6: =COUNTIF(Strips!$T$3:$T$62,$A6) -> 0 | I6: =COUNTIF(Strips!$U$3:$U$62,$A6) -> 5 | J6: =COUNTIF(Strips!$V$3:$V$62,$A6) -> 5 | K6: =COUNTIF(Strips!$W$3:$W$62,$A6) -> 5 | L6: =COUNTIF(Strips!$X$3:$X$62,$A6) -> 0 | O6: Base game line RTP | P6: =G54 -> 0.63440905 | Q6: 0.63440905
A7: STAR | B7: =COUNTIF(Strips!$H$3:$H$62,$A7) -> 1 | C7: =COUNTIF(Strips!$I$3:$I$62,$A7) -> 2 | D7: =COUNTIF(Strips!$J$3:$J$62,$A7) -> 1 | E7: =COUNTIF(Strips!$K$3:$K$62,$A7) -> 2 | F7: =COUNTIF(Strips!$L$3:$L$62,$A7) -> 1 | H7: =COUNTIF(Strips!$T$3:$T$62,$A7) -> 1 | I7: =COUNTIF(Strips!$U$3:$U$62,$A7) -> 1 | J7: =COUNTIF(Strips!$V$3:$V$62,$A7) -> 1 | K7: =COUNTIF(Strips!$W$3:$W$62,$A7) -> 1 | L7: =COUNTIF(Strips!$X$3:$X$62,$A7) -> 1 | O7: Base game STAR scatter RTP | P7: =$E$102 -> 0.021016053 | Q7: 0.021016053
A8: SEVEN | B8: =COUNTIF(Strips!$H$3:$H$62,$A8) -> 1 | C8: =COUNTIF(Strips!$I$3:$I$62,$A8) -> 1 | D8: =COUNTIF(Strips!$J$3:$J$62,$A8) -> 1 | E8: =COUNTIF(Strips!$K$3:$K$62,$A8) -> 2 | F8: =COUNTIF(Strips!$L$3:$L$62,$A8) -> 1 | H8: =COUNTIF(Strips!$T$3:$T$62,$A8) -> 2 | I8: =COUNTIF(Strips!$U$3:$U$62,$A8) -> 2 | J8: =COUNTIF(Strips!$V$3:$V$62,$A8) -> 2 | K8: =COUNTIF(Strips!$W$3:$W$62,$A8) -> 2 | L8: =COUNTIF(Strips!$X$3:$X$62,$A8) -> 2 | O8: Base game RTP | P8: =P6+P7 -> 0.6554251
A9: BAR | B9: =COUNTIF(Strips!$H$3:$H$62,$A9) -> 2 | C9: =COUNTIF(Strips!$I$3:$I$62,$A9) -> 2 | D9: =COUNTIF(Strips!$J$3:$J$62,$A9) -> 2 | E9: =COUNTIF(Strips!$K$3:$K$62,$A9) -> 2 | F9: =COUNTIF(Strips!$L$3:$L$62,$A9) -> 2 | H9: =COUNTIF(Strips!$T$3:$T$62,$A9) -> 2 | I9: =COUNTIF(Strips!$U$3:$U$62,$A9) -> 2 | J9: =COUNTIF(Strips!$V$3:$V$62,$A9) -> 2 | K9: =COUNTIF(Strips!$W$3:$W$62,$A9) -> 2 | L9: =COUNTIF(Strips!$X$3:$X$62,$A9) -> 2 | O9: P(trigger) per base spin | P9: =$E$103 -> 0.0084333001 | Q9: 0.0084333001
A10: BELL | B10: =COUNTIF(Strips!$H$3:$H$62,$A10) -> 2 | C10: =COUNTIF(Strips!$I$3:$I$62,$A10) -> 2 | D10: =COUNTIF(Strips!$J$3:$J$62,$A10) -> 2 | E10: =COUNTIF(Strips!$K$3:$K$62,$A10) -> 2 | F10: =COUNTIF(Strips!$L$3:$L$62,$A10) -> 2 | H10: =COUNTIF(Strips!$T$3:$T$62,$A10) -> 3 | I10: =COUNTIF(Strips!$U$3:$U$62,$A10) -> 2 | J10: =COUNTIF(Strips!$V$3:$V$62,$A10) -> 2 | K10: =COUNTIF(Strips!$W$3:$W$62,$A10) -> 2 | L10: =COUNTIF(Strips!$X$3:$X$62,$A10) -> 3 | O10: Free-spin line RTP per spin (raw) | P10: =G90 -> 1.0427217 | Q10: 1.0427217
A11: MELON | B11: =COUNTIF(Strips!$H$3:$H$62,$A11) -> 3 | C11: =COUNTIF(Strips!$I$3:$I$62,$A11) -> 3 | D11: =COUNTIF(Strips!$J$3:$J$62,$A11) -> 3 | E11: =COUNTIF(Strips!$K$3:$K$62,$A11) -> 3 | F11: =COUNTIF(Strips!$L$3:$L$62,$A11) -> 3 | H11: =COUNTIF(Strips!$T$3:$T$62,$A11) -> 3 | I11: =COUNTIF(Strips!$U$3:$U$62,$A11) -> 3 | J11: =COUNTIF(Strips!$V$3:$V$62,$A11) -> 3 | K11: =COUNTIF(Strips!$W$3:$W$62,$A11) -> 3 | L11: =COUNTIF(Strips!$X$3:$X$62,$A11) -> 3 | O11: Free-spin scatter RTP per spin (raw) | P11: =$E$115 -> 0.014719572 | Q11: 0.014719572
A12: PLUM | B12: =COUNTIF(Strips!$H$3:$H$62,$A12) -> 3 | C12: =COUNTIF(Strips!$I$3:$I$62,$A12) -> 3 | D12: =COUNTIF(Strips!$J$3:$J$62,$A12) -> 3 | E12: =COUNTIF(Strips!$K$3:$K$62,$A12) -> 3 | F12: =COUNTIF(Strips!$L$3:$L$62,$A12) -> 3 | H12: =COUNTIF(Strips!$T$3:$T$62,$A12) -> 3 | I12: =COUNTIF(Strips!$U$3:$U$62,$A12) -> 3 | J12: =COUNTIF(Strips!$V$3:$V$62,$A12) -> 3 | K12: =COUNTIF(Strips!$W$3:$W$62,$A12) -> 3 | L12: =COUNTIF(Strips!$X$3:$X$62,$A12) -> 3 | O12: P(retrigger) per free spin | P12: =$E$116 -> 0.0059924168 | Q12: 0.0059924168
A13: A | B13: =COUNTIF(Strips!$H$3:$H$62,$A13) -> 4 | C13: =COUNTIF(Strips!$I$3:$I$62,$A13) -> 4 | D13: =COUNTIF(Strips!$J$3:$J$62,$A13) -> 4 | E13: =COUNTIF(Strips!$K$3:$K$62,$A13) -> 4 | F13: =COUNTIF(Strips!$L$3:$L$62,$A13) -> 4 | H13: =COUNTIF(Strips!$T$3:$T$62,$A13) -> 3 | I13: =COUNTIF(Strips!$U$3:$U$62,$A13) -> 3 | J13: =COUNTIF(Strips!$V$3:$V$62,$A13) -> 3 | K13: =COUNTIF(Strips!$W$3:$W$62,$A13) -> 3 | L13: =COUNTIF(Strips!$X$3:$X$62,$A13) -> 3 | O13: Free-spin multiplier | P13: =Inputs!$B$10 -> 3
A14: K | B14: =COUNTIF(Strips!$H$3:$H$62,$A14) -> 5 | C14: =COUNTIF(Strips!$I$3:$I$62,$A14) -> 4 | D14: =COUNTIF(Strips!$J$3:$J$62,$A14) -> 4 | E14: =COUNTIF(Strips!$K$3:$K$62,$A14) -> 4 | F14: =COUNTIF(Strips!$L$3:$L$62,$A14) -> 5 | H14: =COUNTIF(Strips!$T$3:$T$62,$A14) -> 4 | I14: =COUNTIF(Strips!$U$3:$U$62,$A14) -> 3 | J14: =COUNTIF(Strips!$V$3:$V$62,$A14) -> 3 | K14: =COUNTIF(Strips!$W$3:$W$62,$A14) -> 3 | L14: =COUNTIF(Strips!$X$3:$X$62,$A14) -> 4 | O14: E[free spins per feature] | P14: =$G$172 -> 10.637375 | Q14: 10.637375
A15: Q | B15: =COUNTIF(Strips!$H$3:$H$62,$A15) -> 6 | C15: =COUNTIF(Strips!$I$3:$I$62,$A15) -> 5 | D15: =COUNTIF(Strips!$J$3:$J$62,$A15) -> 5 | E15: =COUNTIF(Strips!$K$3:$K$62,$A15) -> 5 | F15: =COUNTIF(Strips!$L$3:$L$62,$A15) -> 6 | H15: =COUNTIF(Strips!$T$3:$T$62,$A15) -> 4 | I15: =COUNTIF(Strips!$U$3:$U$62,$A15) -> 3 | J15: =COUNTIF(Strips!$V$3:$V$62,$A15) -> 3 | K15: =COUNTIF(Strips!$W$3:$W$62,$A15) -> 3 | L15: =COUNTIF(Strips!$X$3:$X$62,$A15) -> 4 | O15: Feature value (x total bet) | P15: =P14*P13*(P10+P11) -> 33.745197 | Q15: 33.745197
A16: J | B16: =COUNTIF(Strips!$H$3:$H$62,$A16) -> 6 | C16: =COUNTIF(Strips!$I$3:$I$62,$A16) -> 5 | D16: =COUNTIF(Strips!$J$3:$J$62,$A16) -> 5 | E16: =COUNTIF(Strips!$K$3:$K$62,$A16) -> 5 | F16: =COUNTIF(Strips!$L$3:$L$62,$A16) -> 6 | H16: =COUNTIF(Strips!$T$3:$T$62,$A16) -> 4 | I16: =COUNTIF(Strips!$U$3:$U$62,$A16) -> 3 | J16: =COUNTIF(Strips!$V$3:$V$62,$A16) -> 3 | K16: =COUNTIF(Strips!$W$3:$W$62,$A16) -> 3 | L16: =COUNTIF(Strips!$X$3:$X$62,$A16) -> 4 | O16: Free-spin feature RTP | P16: =P9*P15 -> 0.28458338 | Q16: 0.28458338
A17: 10 | B17: =COUNTIF(Strips!$H$3:$H$62,$A17) -> 7 | C17: =COUNTIF(Strips!$I$3:$I$62,$A17) -> 6 | D17: =COUNTIF(Strips!$J$3:$J$62,$A17) -> 6 | E17: =COUNTIF(Strips!$K$3:$K$62,$A17) -> 5 | F17: =COUNTIF(Strips!$L$3:$L$62,$A17) -> 7 | H17: =COUNTIF(Strips!$T$3:$T$62,$A17) -> 5 | I17: =COUNTIF(Strips!$U$3:$U$62,$A17) -> 4 | J17: =COUNTIF(Strips!$V$3:$V$62,$A17) -> 4 | K17: =COUNTIF(Strips!$W$3:$W$62,$A17) -> 4 | L17: =COUNTIF(Strips!$X$3:$X$62,$A17) -> 5 | O17: THEORETICAL RTP before 5,000x cap | P17: =P8+P16 -> 0.94000848 | Q17: 0.94000848
A18: Strip length | B18: =SUM(B6:B17) -> 40 | C18: =SUM(C6:C17) -> 42 | D18: =SUM(D6:D17) -> 42 | E18: =SUM(E6:E17) -> 41 | F18: =SUM(F6:F17) -> 40 | H18: =SUM(H6:H17) -> 34 | I18: =SUM(I6:I17) -> 34 | J18: =SUM(J6:J17) -> 34 | K18: =SUM(K6:K17) -> 34 | L18: =SUM(L6:L17) -> 34 | O18: Excel minus Python (uncapped) | P18: =P17-Q17 -> 0
A19: Full cycle (all stop combos) | B19: =PRODUCT(B18:F18) -> 115718400 | H19: =PRODUCT(H18:L18) -> 45435424 | O19: Max-win cap adjustment (exact DP, Python) | P19: -6.0492002e-44
O20: FINAL THEORETICAL RTP | P20: =P17+P19 -> 0.94000848 | Q20: 0.94000848
A21: 2. Base game line wins (exact, from strip counts) | O21: Hold (house edge) | P21: =1-P20 -> 0.059991523
A22: Symbol | B22: OAK | C22: Pay x line | D22: Combos (per line, full cycle) | E22: Prob per line | F22: 1 in | G22: RTP contribution
A23: SEVEN | B23: 2 | C23: =INDEX(Inputs!$B$16:$E$16,1,1) -> 2 | D23: =$B$8*($C$8+$C$6)*($D$18-($D$8+$D$6))*$E$18*$F$18 -> 344400 | E23: =D23/$B$19 -> 0.0029761905 | F23: =IF(E23>0,1/E23,"-") -> 336 | G23: =C23*E23 -> 0.005952381
A24: SEVEN | B24: 3 | C24: =INDEX(Inputs!$B$16:$E$16,1,2) -> 50 | D24: =$B$8*($C$8+$C$6)*($D$8+$D$6)*($E$18-($E$8+$E$6))*$F$18 -> 58800 | E24: =D24/$B$19 -> 0.00050813008 | F24: =IF(E24>0,1/E24,"-") -> 1968 | G24: =C24*E24 -> 0.025406504 | O24: RTP BY SYMBOL / FEATURE (live)
A25: SEVEN | B25: 4 | C25: =INDEX(Inputs!$B$16:$E$16,1,3) -> 250 | D25: =$B$8*($C$8+$C$6)*($D$8+$D$6)*($E$8+$E$6)*($F$18-($F$8+$F$6)) -> 9828 | E25: =D25/$B$19 -> 8.4930314e-05 | F25: =IF(E25>0,1/E25,"-") -> 11774.359 | G25: =C25*E25 -> 0.021232578 | O25: Source | P25: Base game | Q25: Free spins | R25: Total | S25: Share of RTP
A26: SEVEN | B26: 5 | C26: =INDEX(Inputs!$B$16:$E$16,1,4) -> 1000 | D26: =$B$8*($C$8+$C$6)*($D$8+$D$6)*($E$8+$E$6)*($F$8+$F$6) -> 252 | E26: =D26/$B$19 -> 2.1777003e-06 | F26: =IF(E26>0,1/E26,"-") -> 459200 | G26: =C26*E26 -> 0.0021777003 | O26: SEVEN lines | P26: =SUMIF($A$23:$A$53,"SEVEN",$G$23:$G$53) -> 0.054769164 | Q26: =P9*P14*P13*SUMIF($A$59:$A$89,"SEVEN",$G$59:$G$89) -> 0.072453771 | R26: =P26+Q26 -> 0.12722293 | S26: =R26/P20 -> 0.13534233
A27: BAR | B27: 3 | C27: =INDEX(Inputs!$B$17:$E$17,1,2) -> 30 | D27: =$B$9*($C$9+$C$6)*($D$9+$D$6)*($E$18-($E$9+$E$6))*$F$18 -> 156800 | E27: =D27/$B$19 -> 0.0013550136 | F27: =IF(E27>0,1/E27,"-") -> 738 | G27: =C27*E27 -> 0.040650407 | O27: BAR lines | P27: =SUMIF($A$23:$A$53,"BAR",$G$23:$G$53) -> 0.072938444 | Q27: =P9*P14*P13*SUMIF($A$59:$A$89,"BAR",$G$59:$G$89) -> 0.035652877 | R27: =P27+Q27 -> 0.10859132 | S27: =R27/P20 -> 0.11552164
A28: BAR | B28: 4 | C28: =INDEX(Inputs!$B$17:$E$17,1,3) -> 120 | D28: =$B$9*($C$9+$C$6)*($D$9+$D$6)*($E$9+$E$6)*($F$18-($F$9+$F$6)) -> 25536 | E28: =D28/$B$19 -> 0.00022067364 | F28: =IF(E28>0,1/E28,"-") -> 4531.5789 | G28: =C28*E28 -> 0.026480836 | O28: BELL lines | P28: =SUMIF($A$23:$A$53,"BELL",$G$23:$G$53) -> 0.048238482 | Q28: =P9*P14*P13*SUMIF($A$59:$A$89,"BELL",$G$59:$G$89) -> 0.036587444 | R28: =P28+Q28 -> 0.084825927 | S28: =R28/P20 -> 0.090239534
A29: BAR | B29: 5 | C29: =INDEX(Inputs!$B$17:$E$17,1,4) -> 500 | D29: =$B$9*($C$9+$C$6)*($D$9+$D$6)*($E$9+$E$6)*($F$9+$F$6) -> 1344 | E29: =D29/$B$19 -> 1.1614402e-05 | F29: =IF(E29>0,1/E29,"-") -> 86100 | G29: =C29*E29 -> 0.0058072009 | O29: MELON lines | P29: =SUMIF($A$23:$A$53,"MELON",$G$23:$G$53) -> 0.068130911 | Q29: =P9*P14*P13*SUMIF($A$59:$A$89,"MELON",$G$59:$G$89) -> 0.033276239 | R29: =P29+Q29 -> 0.10140715 | S29: =R29/P20 -> 0.10787897
A30: BELL | B30: 3 | C30: =INDEX(Inputs!$B$18:$E$18,1,2) -> 20 | D30: =$B$10*($C$10+$C$6)*($D$10+$D$6)*($E$18-($E$10+$E$6))*$F$18 -> 156800 | E30: =D30/$B$19 -> 0.0013550136 | F30: =IF(E30>0,1/E30,"-") -> 738 | G30: =C30*E30 -> 0.027100271 | O30: PLUM lines | P30: =SUMIF($A$23:$A$53,"PLUM",$G$23:$G$53) -> 0.049623569 | Q30: =P9*P14*P13*SUMIF($A$59:$A$89,"PLUM",$G$59:$G$89) -> 0.024746786 | R30: =P30+Q30 -> 0.074370355 | S30: =R30/P20 -> 0.079116686
A31: BELL | B31: 4 | C31: =INDEX(Inputs!$B$18:$E$18,1,3) -> 80 | D31: =$B$10*($C$10+$C$6)*($D$10+$D$6)*($E$10+$E$6)*($F$18-($F$10+$F$6)) -> 25536 | E31: =D31/$B$19 -> 0.00022067364 | F31: =IF(E31>0,1/E31,"-") -> 4531.5789 | G31: =C31*E31 -> 0.017653891 | O31: A lines | P31: =SUMIF($A$23:$A$53,"A",$G$23:$G$53) -> 0.052887008 | Q31: =P9*P14*P13*SUMIF($A$59:$A$89,"A",$G$59:$G$89) -> 0.01480713 | R31: =P31+Q31 -> 0.067694139 | S31: =R31/P20 -> 0.072014392
A32: BELL | B32: 5 | C32: =INDEX(Inputs!$B$18:$E$18,1,4) -> 300 | D32: =$B$10*($C$10+$C$6)*($D$10+$D$6)*($E$10+$E$6)*($F$10+$F$6) -> 1344 | E32: =D32/$B$19 -> 1.1614402e-05 | F32: =IF(E32>0,1/E32,"-") -> 86100 | G32: =C32*E32 -> 0.0034843206 | O32: K lines | P32: =SUMIF($A$23:$A$53,"K",$G$23:$G$53) -> 0.05988676 | Q32: =P9*P14*P13*SUMIF($A$59:$A$89,"K",$G$59:$G$89) -> 0.01786257 | R32: =P32+Q32 -> 0.07774933 | S32: =R32/P20 -> 0.082711307
A33: MELON | B33: 3 | C33: =INDEX(Inputs!$B$19:$E$19,1,2) -> 15 | D33: =$B$11*($C$11+$C$6)*($D$11+$D$6)*($E$18-($E$11+$E$6))*$F$18 -> 293760 | E33: =D33/$B$19 -> 0.0025385764 | F33: =IF(E33>0,1/E33,"-") -> 393.92157 | G33: =C33*E33 -> 0.038078646 | O33: Q lines | P33: =SUMIF($A$23:$A$53,"Q",$G$23:$G$53) -> 0.081160818 | Q33: =P9*P14*P13*SUMIF($A$59:$A$89,"Q",$G$59:$G$89) -> 0.015072491 | R33: =P33+Q33 -> 0.096233309 | S33: =R33/P20 -> 0.10237494
A34: MELON | B34: 4 | C34: =INDEX(Inputs!$B$19:$E$19,1,3) -> 50 | D34: =$B$11*($C$11+$C$6)*($D$11+$D$6)*($E$11+$E$6)*($F$18-($F$11+$F$6)) -> 55944 | E34: =D34/$B$19 -> 0.00048344948 | F34: =IF(E34>0,1/E34,"-") -> 2068.4685 | G34: =C34*E34 -> 0.024172474 | O34: J lines | P34: =SUMIF($A$23:$A$53,"J",$G$23:$G$53) -> 0.06205409 | Q34: =P9*P14*P13*SUMIF($A$59:$A$89,"J",$G$59:$G$89) -> 0.011427193 | R34: =P34+Q34 -> 0.073481282 | S34: =R34/P20 -> 0.078170872
A35: MELON | B35: 5 | C35: =INDEX(Inputs!$B$19:$E$19,1,4) -> 150 | D35: =$B$11*($C$11+$C$6)*($D$11+$D$6)*($E$11+$E$6)*($F$11+$F$6) -> 4536 | E35: =D35/$B$19 -> 3.9198606e-05 | F35: =IF(E35>0,1/E35,"-") -> 25511.111 | G35: =C35*E35 -> 0.0058797909 | O35: 10 lines | P35: =SUMIF($A$23:$A$53,"10",$G$23:$G$53) -> 0.084719803 | Q35: =P9*P14*P13*SUMIF($A$59:$A$89,"10",$G$59:$G$89) -> 0.018735477 | R35: =P35+Q35 -> 0.10345528 | S35: =R35/P20 -> 0.11005782
A36: PLUM | B36: 3 | C36: =INDEX(Inputs!$B$20:$E$20,1,2) -> 10 | D36: =$B$12*($C$12+$C$6)*($D$12+$D$6)*($E$18-($E$12+$E$6))*$F$18 -> 293760 | E36: =D36/$B$19 -> 0.0025385764 | F36: =IF(E36>0,1/E36,"-") -> 393.92157 | G36: =C36*E36 -> 0.025385764 | O36: STAR scatter pays | P36: =$E$102 -> 0.021016053 | Q36: =P9*P14*P13*$E$115 -> 0.0039613978 | R36: =P36+Q36 -> 0.024977451 | S36: =R36/P20 -> 0.026571516
A37: PLUM | B37: 4 | C37: =INDEX(Inputs!$B$20:$E$20,1,3) -> 40 | D37: =$B$12*($C$12+$C$6)*($D$12+$D$6)*($E$12+$E$6)*($F$18-($F$12+$F$6)) -> 55944 | E37: =D37/$B$19 -> 0.00048344948 | F37: =IF(E37>0,1/E37,"-") -> 2068.4685 | G37: =C37*E37 -> 0.019337979 | O37: Max-win cap | R37: =P19 -> -6.0492002e-44
A38: PLUM | B38: 5 | C38: =INDEX(Inputs!$B$20:$E$20,1,4) -> 125 | D38: =$B$12*($C$12+$C$6)*($D$12+$D$6)*($E$12+$E$6)*($F$12+$F$6) -> 4536 | E38: =D38/$B$19 -> 3.9198606e-05 | F38: =IF(E38>0,1/E38,"-") -> 25511.111 | G38: =C38*E38 -> 0.0048998258 | O38: Total | P38: =SUM(P26:P36) -> 0.6554251 | Q38: =SUM(Q26:Q36) -> 0.28458338 | R38: =SUM(R26:R37) -> 0.94000848
A39: A | B39: 3 | C39: =INDEX(Inputs!$B$21:$E$21,1,2) -> 5 | D39: =$B$13*($C$13+$C$6)*($D$13+$D$6)*($E$18-($E$13+$E$6))*$F$18 -> 475200 | E39: =D39/$B$19 -> 0.0041065207 | F39: =IF(E39>0,1/E39,"-") -> 243.51515 | G39: =C39*E39 -> 0.020532603 | O39: Check vs final RTP | R39: =R38-P20 -> 0
A40: A | B40: 4 | C40: =INDEX(Inputs!$B$21:$E$21,1,3) -> 25 | D40: =$B$13*($C$13+$C$6)*($D$13+$D$6)*($E$13+$E$6)*($F$18-($F$13+$F$6)) -> 103680 | E40: =D40/$B$19 -> 0.00089596814 | F40: =IF(E40>0,1/E40,"-") -> 1116.1111 | G40: =C40*E40 -> 0.022399204
A41: A | B41: 5 | C41: =INDEX(Inputs!$B$21:$E$21,1,4) -> 100 | D41: =$B$13*($C$13+$C$6)*($D$13+$D$6)*($E$13+$E$6)*($F$13+$F$6) -> 11520 | E41: =D41/$B$19 -> 9.9552016e-05 | F41: =IF(E41>0,1/E41,"-") -> 10045 | G41: =C41*E41 -> 0.0099552016
...

Sheet PAR_92
A1: PAR sheet — Lucky Sevens 20, 92% variant
A2: Black = live formula; blue = input; green = link to another tab; purple italic = value imported from the Python full-cycle / simulation run (for comparison only).
A4: 1. Reel strip symbol counts (COUNTIF over the Strips tab) | O4: RTP SUMMARY (live)
A5: Symbol | B5: Base R1 | C5: Base R2 | D5: Base R3 | E5: Base R4 | F5: Base R5 | H5: FS R1 | I5: FS R2 | J5: FS R3 | K5: FS R4 | L5: FS R5 | O5: Component | P5: Excel (formula) | Q5: Python exact
A6: WILD | B6: =COUNTIF(Strips!$N$3:$N$62,$A6) -> 0 | C6: =COUNTIF(Strips!$O$3:$O$62,$A6) -> 5 | D6: =COUNTIF(Strips!$P$3:$P$62,$A6) -> 5 | E6: =COUNTIF(Strips!$Q$3:$Q$62,$A6) -> 5 | F6: =COUNTIF(Strips!$R$3:$R$62,$A6) -> 0 | H6: =COUNTIF(Strips!$T$3:$T$62,$A6) -> 0 | I6: =COUNTIF(Strips!$U$3:$U$62,$A6) -> 5 | J6: =COUNTIF(Strips!$V$3:$V$62,$A6) -> 5 | K6: =COUNTIF(Strips!$W$3:$W$62,$A6) -> 5 | L6: =COUNTIF(Strips!$X$3:$X$62,$A6) -> 0 | O6: Base game line RTP | P6: =G54 -> 0.61594172 | Q6: 0.61594172
A7: STAR | B7: =COUNTIF(Strips!$N$3:$N$62,$A7) -> 1 | C7: =COUNTIF(Strips!$O$3:$O$62,$A7) -> 2 | D7: =COUNTIF(Strips!$P$3:$P$62,$A7) -> 1 | E7: =COUNTIF(Strips!$Q$3:$Q$62,$A7) -> 2 | F7: =COUNTIF(Strips!$R$3:$R$62,$A7) -> 1 | H7: =COUNTIF(Strips!$T$3:$T$62,$A7) -> 1 | I7: =COUNTIF(Strips!$U$3:$U$62,$A7) -> 1 | J7: =COUNTIF(Strips!$V$3:$V$62,$A7) -> 1 | K7: =COUNTIF(Strips!$W$3:$W$62,$A7) -> 1 | L7: =COUNTIF(Strips!$X$3:$X$62,$A7) -> 1 | O7: Base game STAR scatter RTP | P7: =$E$102 -> 0.02091899 | Q7: 0.02091899
A8: SEVEN | B8: =COUNTIF(Strips!$N$3:$N$62,$A8) -> 1 | C8: =COUNTIF(Strips!$O$3:$O$62,$A8) -> 1 | D8: =COUNTIF(Strips!$P$3:$P$62,$A8) -> 1 | E8: =COUNTIF(Strips!$Q$3:$Q$62,$A8) -> 2 | F8: =COUNTIF(Strips!$R$3:$R$62,$A8) -> 1 | H8: =COUNTIF(Strips!$T$3:$T$62,$A8) -> 2 | I8: =COUNTIF(Strips!$U$3:$U$62,$A8) -> 2 | J8: =COUNTIF(Strips!$V$3:$V$62,$A8) -> 2 | K8: =COUNTIF(Strips!$W$3:$W$62,$A8) -> 2 | L8: =COUNTIF(Strips!$X$3:$X$62,$A8) -> 2 | O8: Base game RTP | P8: =P6+P7 -> 0.63686071
A9: BAR | B9: =COUNTIF(Strips!$N$3:$N$62,$A9) -> 2 | C9: =COUNTIF(Strips!$O$3:$O$62,$A9) -> 2 | D9: =COUNTIF(Strips!$P$3:$P$62,$A9) -> 2 | E9: =COUNTIF(Strips!$Q$3:$Q$62,$A9) -> 2 | F9: =COUNTIF(Strips!$R$3:$R$62,$A9) -> 2 | H9: =COUNTIF(Strips!$T$3:$T$62,$A9) -> 2 | I9: =COUNTIF(Strips!$U$3:$U$62,$A9) -> 2 | J9: =COUNTIF(Strips!$V$3:$V$62,$A9) -> 2 | K9: =COUNTIF(Strips!$W$3:$W$62,$A9) -> 2 | L9: =COUNTIF(Strips!$X$3:$X$62,$A9) -> 2 | O9: P(trigger) per base spin | P9: =$E$103 -> 0.0083903683 | Q9: 0.0083903683
A10: BELL | B10: =COUNTIF(Strips!$N$3:$N$62,$A10) -> 3 | C10: =COUNTIF(Strips!$O$3:$O$62,$A10) -> 2 | D10: =COUNTIF(Strips!$P$3:$P$62,$A10) -> 2 | E10: =COUNTIF(Strips!$Q$3:$Q$62,$A10) -> 2 | F10: =COUNTIF(Strips!$R$3:$R$62,$A10) -> 2 | H10: =COUNTIF(Strips!$T$3:$T$62,$A10) -> 3 | I10: =COUNTIF(Strips!$U$3:$U$62,$A10) -> 2 | J10: =COUNTIF(Strips!$V$3:$V$62,$A10) -> 2 | K10: =COUNTIF(Strips!$W$3:$W$62,$A10) -> 2 | L10: =COUNTIF(Strips!$X$3:$X$62,$A10) -> 3 | O10: Free-spin line RTP per spin (raw) | P10: =G90 -> 1.0427217 | Q10: 1.0427217
A11: MELON | B11: =COUNTIF(Strips!$N$3:$N$62,$A11) -> 3 | C11: =COUNTIF(Strips!$O$3:$O$62,$A11) -> 3 | D11: =COUNTIF(Strips!$P$3:$P$62,$A11) -> 3 | E11: =COUNTIF(Strips!$Q$3:$Q$62,$A11) -> 3 | F11: =COUNTIF(Strips!$R$3:$R$62,$A11) -> 3 | H11: =COUNTIF(Strips!$T$3:$T$62,$A11) -> 3 | I11: =COUNTIF(Strips!$U$3:$U$62,$A11) -> 3 | J11: =COUNTIF(Strips!$V$3:$V$62,$A11) -> 3 | K11: =COUNTIF(Strips!$W$3:$W$62,$A11) -> 3 | L11: =COUNTIF(Strips!$X$3:$X$62,$A11) -> 3 | O11: Free-spin scatter RTP per spin (raw) | P11: =$E$115 -> 0.014719572 | Q11: 0.014719572
A12: PLUM | B12: =COUNTIF(Strips!$N$3:$N$62,$A12) -> 3 | C12: =COUNTIF(Strips!$O$3:$O$62,$A12) -> 3 | D12: =COUNTIF(Strips!$P$3:$P$62,$A12) -> 3 | E12: =COUNTIF(Strips!$Q$3:$Q$62,$A12) -> 3 | F12: =COUNTIF(Strips!$R$3:$R$62,$A12) -> 3 | H12: =COUNTIF(Strips!$T$3:$T$62,$A12) -> 3 | I12: =COUNTIF(Strips!$U$3:$U$62,$A12) -> 3 | J12: =COUNTIF(Strips!$V$3:$V$62,$A12) -> 3 | K12: =COUNTIF(Strips!$W$3:$W$62,$A12) -> 3 | L12: =COUNTIF(Strips!$X$3:$X$62,$A12) -> 3 | O12: P(retrigger) per free spin | P12: =$E$116 -> 0.0059924168 | Q12: 0.0059924168
A13: A | B13: =COUNTIF(Strips!$N$3:$N$62,$A13) -> 4 | C13: =COUNTIF(Strips!$O$3:$O$62,$A13) -> 4 | D13: =COUNTIF(Strips!$P$3:$P$62,$A13) -> 4 | E13: =COUNTIF(Strips!$Q$3:$Q$62,$A13) -> 4 | F13: =COUNTIF(Strips!$R$3:$R$62,$A13) -> 5 | H13: =COUNTIF(Strips!$T$3:$T$62,$A13) -> 3 | I13: =COUNTIF(Strips!$U$3:$U$62,$A13) -> 3 | J13: =COUNTIF(Strips!$V$3:$V$62,$A13) -> 3 | K13: =COUNTIF(Strips!$W$3:$W$62,$A13) -> 3 | L13: =COUNTIF(Strips!$X$3:$X$62,$A13) -> 3 | O13: Free-spin multiplier | P13: =Inputs!$B$10 -> 3
A14: K | B14: =COUNTIF(Strips!$N$3:$N$62,$A14) -> 5 | C14: =COUNTIF(Strips!$O$3:$O$62,$A14) -> 4 | D14: =COUNTIF(Strips!$P$3:$P$62,$A14) -> 4 | E14: =COUNTIF(Strips!$Q$3:$Q$62,$A14) -> 4 | F14: =COUNTIF(Strips!$R$3:$R$62,$A14) -> 5 | H14: =COUNTIF(Strips!$T$3:$T$62,$A14) -> 4 | I14: =COUNTIF(Strips!$U$3:$U$62,$A14) -> 3 | J14: =COUNTIF(Strips!$V$3:$V$62,$A14) -> 3 | K14: =COUNTIF(Strips!$W$3:$W$62,$A14) -> 3 | L14: =COUNTIF(Strips!$X$3:$X$62,$A14) -> 4 | O14: E[free spins per feature] | P14: =$G$172 -> 10.637375 | Q14: 10.637375
A15: Q | B15: =COUNTIF(Strips!$N$3:$N$62,$A15) -> 5 | C15: =COUNTIF(Strips!$O$3:$O$62,$A15) -> 5 | D15: =COUNTIF(Strips!$P$3:$P$62,$A15) -> 5 | E15: =COUNTIF(Strips!$Q$3:$Q$62,$A15) -> 4 | F15: =COUNTIF(Strips!$R$3:$R$62,$A15) -> 5 | H15: =COUNTIF(Strips!$T$3:$T$62,$A15) -> 4 | I15: =COUNTIF(Strips!$U$3:$U$62,$A15) -> 3 | J15: =COUNTIF(Strips!$V$3:$V$62,$A15) -> 3 | K15: =COUNTIF(Strips!$W$3:$W$62,$A15) -> 3 | L15: =COUNTIF(Strips!$X$3:$X$62,$A15) -> 4 | O15: Feature value (x total bet) | P15: =P14*P13*(P10+P11) -> 33.745197 | Q15: 33.745197
A16: J | B16: =COUNTIF(Strips!$N$3:$N$62,$A16) -> 6 | C16: =COUNTIF(Strips!$O$3:$O$62,$A16) -> 5 | D16: =COUNTIF(Strips!$P$3:$P$62,$A16) -> 5 | E16: =COUNTIF(Strips!$Q$3:$Q$62,$A16) -> 5 | F16: =COUNTIF(Strips!$R$3:$R$62,$A16) -> 6 | H16: =COUNTIF(Strips!$T$3:$T$62,$A16) -> 4 | I16: =COUNTIF(Strips!$U$3:$U$62,$A16) -> 3 | J16: =COUNTIF(Strips!$V$3:$V$62,$A16) -> 3 | K16: =COUNTIF(Strips!$W$3:$W$62,$A16) -> 3 | L16: =COUNTIF(Strips!$X$3:$X$62,$A16) -> 4 | O16: Free-spin feature RTP | P16: =P9*P15 -> 0.28313463 | Q16: 0.28313463
A17: 10 | B17: =COUNTIF(Strips!$N$3:$N$62,$A17) -> 7 | C17: =COUNTIF(Strips!$O$3:$O$62,$A17) -> 6 | D17: =COUNTIF(Strips!$P$3:$P$62,$A17) -> 6 | E17: =COUNTIF(Strips!$Q$3:$Q$62,$A17) -> 6 | F17: =COUNTIF(Strips!$R$3:$R$62,$A17) -> 7 | H17: =COUNTIF(Strips!$T$3:$T$62,$A17) -> 5 | I17: =COUNTIF(Strips!$U$3:$U$62,$A17) -> 4 | J17: =COUNTIF(Strips!$V$3:$V$62,$A17) -> 4 | K17: =COUNTIF(Strips!$W$3:$W$62,$A17) -> 4 | L17: =COUNTIF(Strips!$X$3:$X$62,$A17) -> 5 | O17: THEORETICAL RTP before 5,000x cap | P17: =P8+P16 -> 0.91999534 | Q17: 0.91999534
A18: Strip length | B18: =SUM(B6:B17) -> 40 | C18: =SUM(C6:C17) -> 42 | D18: =SUM(D6:D17) -> 41 | E18: =SUM(E6:E17) -> 42 | F18: =SUM(F6:F17) -> 40 | H18: =SUM(H6:H17) -> 34 | I18: =SUM(I6:I17) -> 34 | J18: =SUM(J6:J17) -> 34 | K18: =SUM(K6:K17) -> 34 | L18: =SUM(L6:L17) -> 34 | O18: Excel minus Python (uncapped) | P18: =P17-Q17 -> 0
A19: Full cycle (all stop combos) | B19: =PRODUCT(B18:F18) -> 115718400 | H19: =PRODUCT(H18:L18) -> 45435424 | O19: Max-win cap adjustment (exact DP, Python) | P19: -6.0221097e-44
O20: FINAL THEORETICAL RTP | P20: =P17+P19 -> 0.91999534 | Q20: 0.91999534
A21: 2. Base game line wins (exact, from strip counts) | O21: Hold (house edge) | P21: =1-P20 -> 0.080004659
A22: Symbol | B22: OAK | C22: Pay x line | D22: Combos (per line, full cycle) | E22: Prob per line | F22: 1 in | G22: RTP contribution
A23: SEVEN | B23: 2 | C23: =INDEX(Inputs!$B$16:$E$16,1,1) -> 2 | D23: =$B$8*($C$8+$C$6)*($D$18-($D$8+$D$6))*$E$18*$F$18 -> 352800 | E23: =D23/$B$19 -> 0.0030487805 | F23: =IF(E23>0,1/E23,"-") -> 328 | G23: =C23*E23 -> 0.006097561
A24: SEVEN | B24: 3 | C24: =INDEX(Inputs!$B$16:$E$16,1,2) -> 50 | D24: =$B$8*($C$8+$C$6)*($D$8+$D$6)*($E$18-($E$8+$E$6))*$F$18 -> 50400 | E24: =D24/$B$19 -> 0.00043554007 | F24: =IF(E24>0,1/E24,"-") -> 2296 | G24: =C24*E24 -> 0.021777003 | O24: RTP BY SYMBOL / FEATURE (live)
A25: SEVEN | B25: 4 | C25: =INDEX(Inputs!$B$16:$E$16,1,3) -> 250 | D25: =$B$8*($C$8+$C$6)*($D$8+$D$6)*($E$8+$E$6)*($F$18-($F$8+$F$6)) -> 9828 | E25: =D25/$B$19 -> 8.4930314e-05 | F25: =IF(E25>0,1/E25,"-") -> 11774.359 | G25: =C25*E25 -> 0.021232578 | O25: Source | P25: Base game | Q25: Free spins | R25: Total | S25: Share of RTP
A26: SEVEN | B26: 5 | C26: =INDEX(Inputs!$B$16:$E$16,1,4) -> 1000 | D26: =$B$8*($C$8+$C$6)*($D$8+$D$6)*($E$8+$E$6)*($F$8+$F$6) -> 252 | E26: =D26/$B$19 -> 2.1777003e-06 | F26: =IF(E26>0,1/E26,"-") -> 459200 | G26: =C26*E26 -> 0.0021777003 | O26: SEVEN lines | P26: =SUMIF($A$23:$A$53,"SEVEN",$G$23:$G$53) -> 0.051284843 | Q26: =P9*P14*P13*SUMIF($A$59:$A$89,"SEVEN",$G$59:$G$89) -> 0.072084927 | R26: =P26+Q26 -> 0.12336977 | S26: =R26/P20 -> 0.13409826
A27: BAR | B27: 3 | C27: =INDEX(Inputs!$B$17:$E$17,1,2) -> 30 | D27: =$B$9*($C$9+$C$6)*($D$9+$D$6)*($E$18-($E$9+$E$6))*$F$18 -> 137200 | E27: =D27/$B$19 -> 0.0011856369 | F27: =IF(E27>0,1/E27,"-") -> 843.42857 | G27: =C27*E27 -> 0.035569106 | O27: BAR lines | P27: =SUMIF($A$23:$A$53,"BAR",$G$23:$G$53) -> 0.06852981 | Q27: =P9*P14*P13*SUMIF($A$59:$A$89,"BAR",$G$59:$G$89) -> 0.035471377 | R27: =P27+Q27 -> 0.10400119 | S27: =R27/P20 -> 0.11304534
A28: BAR | B28: 4 | C28: =INDEX(Inputs!$B$17:$E$17,1,3) -> 120 | D28: =$B$9*($C$9+$C$6)*($D$9+$D$6)*($E$9+$E$6)*($F$18-($F$9+$F$6)) -> 26068 | E28: =D28/$B$19 -> 0.000225271 | F28: =IF(E28>0,1/E28,"-") -> 4439.0977 | G28: =C28*E28 -> 0.02703252 | O28: BELL lines | P28: =SUMIF($A$23:$A$53,"BELL",$G$23:$G$53) -> 0.067936992 | Q28: =P9*P14*P13*SUMIF($A$59:$A$89,"BELL",$G$59:$G$89) -> 0.036401187 | R28: =P28+Q28 -> 0.10433818 | S28: =R28/P20 -> 0.11341164
A29: BAR | B29: 5 | C29: =INDEX(Inputs!$B$17:$E$17,1,4) -> 500 | D29: =$B$9*($C$9+$C$6)*($D$9+$D$6)*($E$9+$E$6)*($F$9+$F$6) -> 1372 | E29: =D29/$B$19 -> 1.1856369e-05 | F29: =IF(E29>0,1/E29,"-") -> 84342.857 | G29: =C29*E29 -> 0.0059281843 | O29: MELON lines | P29: =SUMIF($A$23:$A$53,"MELON",$G$23:$G$53) -> 0.06437697 | Q29: =P9*P14*P13*SUMIF($A$59:$A$89,"MELON",$G$59:$G$89) -> 0.033106838 | R29: =P29+Q29 -> 0.097483809 | S29: =R29/P20 -> 0.1059612
A30: BELL | B30: 3 | C30: =INDEX(Inputs!$B$18:$E$18,1,2) -> 20 | D30: =$B$10*($C$10+$C$6)*($D$10+$D$6)*($E$18-($E$10+$E$6))*$F$18 -> 205800 | E30: =D30/$B$19 -> 0.0017784553 | F30: =IF(E30>0,1/E30,"-") -> 562.28571 | G30: =C30*E30 -> 0.035569106 | O30: PLUM lines | P30: =SUMIF($A$23:$A$53,"PLUM",$G$23:$G$53) -> 0.047187656 | Q30: =P9*P14*P13*SUMIF($A$59:$A$89,"PLUM",$G$59:$G$89) -> 0.024620807 | R30: =P30+Q30 -> 0.071808462 | S30: =R30/P20 -> 0.078053072
A31: BELL | B31: 4 | C31: =INDEX(Inputs!$B$18:$E$18,1,3) -> 80 | D31: =$B$10*($C$10+$C$6)*($D$10+$D$6)*($E$10+$E$6)*($F$18-($F$10+$F$6)) -> 39102 | E31: =D31/$B$19 -> 0.0003379065 | F31: =IF(E31>0,1/E31,"-") -> 2959.3985 | G31: =C31*E31 -> 0.02703252 | O31: A lines | P31: =SUMIF($A$23:$A$53,"A",$G$23:$G$53) -> 0.053128111 | Q31: =P9*P14*P13*SUMIF($A$59:$A$89,"A",$G$59:$G$89) -> 0.014731751 | R31: =P31+Q31 -> 0.067859862 | S31: =R31/P20 -> 0.073761093
A32: BELL | B32: 5 | C32: =INDEX(Inputs!$B$18:$E$18,1,4) -> 300 | D32: =$B$10*($C$10+$C$6)*($D$10+$D$6)*($E$10+$E$6)*($F$10+$F$6) -> 2058 | E32: =D32/$B$19 -> 1.7784553e-05 | F32: =IF(E32>0,1/E32,"-") -> 56228.571 | G32: =C32*E32 -> 0.0053353659 | O32: K lines | P32: =SUMIF($A$23:$A$53,"K",$G$23:$G$53) -> 0.057747947 | Q32: =P9*P14*P13*SUMIF($A$59:$A$89,"K",$G$59:$G$89) -> 0.017771636 | R32: =P32+Q32 -> 0.075519583 | S32: =R32/P20 -> 0.082086919
A33: MELON | B33: 3 | C33: =INDEX(Inputs!$B$19:$E$19,1,2) -> 15 | D33: =$B$11*($C$11+$C$6)*($D$11+$D$6)*($E$18-($E$11+$E$6))*$F$18 -> 261120 | E33: =D33/$B$19 -> 0.0022565124 | F33: =IF(E33>0,1/E33,"-") -> 443.16176 | G33: =C33*E33 -> 0.033847685 | O33: Q lines | P33: =SUMIF($A$23:$A$53,"Q",$G$23:$G$53) -> 0.060599697 | Q33: =P9*P14*P13*SUMIF($A$59:$A$89,"Q",$G$59:$G$89) -> 0.014995761 | R33: =P33+Q33 -> 0.075595458 | S33: =R33/P20 -> 0.082169392
A34: MELON | B34: 4 | C34: =INDEX(Inputs!$B$19:$E$19,1,3) -> 50 | D34: =$B$11*($C$11+$C$6)*($D$11+$D$6)*($E$11+$E$6)*($F$18-($F$11+$F$6)) -> 56832 | E34: =D34/$B$19 -> 0.00049112328 | F34: =IF(E34>0,1/E34,"-") -> 2036.1486 | G34: =C34*E34 -> 0.024556164 | O34: J lines | P34: =SUMIF($A$23:$A$53,"J",$G$23:$G$53) -> 0.05973121 | Q34: =P9*P14*P13*SUMIF($A$59:$A$89,"J",$G$59:$G$89) -> 0.01136902 | R34: =P34+Q34 -> 0.071100229 | S34: =R34/P20 -> 0.077283249
A35: MELON | B35: 5 | C35: =INDEX(Inputs!$B$19:$E$19,1,4) -> 150 | D35: =$B$11*($C$11+$C$6)*($D$11+$D$6)*($E$11+$E$6)*($F$11+$F$6) -> 4608 | E35: =D35/$B$19 -> 3.9820806e-05 | F35: =IF(E35>0,1/E35,"-") -> 25112.5 | G35: =C35*E35 -> 0.005973121 | O35: 10 lines | P35: =SUMIF($A$23:$A$53,"10",$G$23:$G$53) -> 0.085418481 | Q35: =P9*P14*P13*SUMIF($A$59:$A$89,"10",$G$59:$G$89) -> 0.018640099 | R35: =P35+Q35 -> 0.10405858 | S35: =R35/P20 -> 0.11310773
A36: PLUM | B36: 3 | C36: =INDEX(Inputs!$B$20:$E$20,1,2) -> 10 | D36: =$B$12*($C$12+$C$6)*($D$12+$D$6)*($E$18-($E$12+$E$6))*$F$18 -> 261120 | E36: =D36/$B$19 -> 0.0022565124 | F36: =IF(E36>0,1/E36,"-") -> 443.16176 | G36: =C36*E36 -> 0.022565124 | O36: STAR scatter pays | P36: =$E$102 -> 0.02091899 | Q36: =P9*P14*P13*$E$115 -> 0.0039412314 | R36: =P36+Q36 -> 0.024860221 | S36: =R36/P20 -> 0.027022116
A37: PLUM | B37: 4 | C37: =INDEX(Inputs!$B$20:$E$20,1,3) -> 40 | D37: =$B$12*($C$12+$C$6)*($D$12+$D$6)*($E$12+$E$6)*($F$18-($F$12+$F$6)) -> 56832 | E37: =D37/$B$19 -> 0.00049112328 | F37: =IF(E37>0,1/E37,"-") -> 2036.1486 | G37: =C37*E37 -> 0.019644931 | O37: Max-win cap | R37: =P19 -> -6.0221097e-44
A38: PLUM | B38: 5 | C38: =INDEX(Inputs!$B$20:$E$20,1,4) -> 125 | D38: =$B$12*($C$12+$C$6)*($D$12+$D$6)*($E$12+$E$6)*($F$12+$F$6) -> 4608 | E38: =D38/$B$19 -> 3.9820806e-05 | F38: =IF(E38>0,1/E38,"-") -> 25112.5 | G38: =C38*E38 -> 0.0049776008 | O38: Total | P38: =SUM(P26:P36) -> 0.63686071 | Q38: =SUM(Q26:Q36) -> 0.28313463 | R38: =SUM(R26:R37) -> 0.91999534
A39: A | B39: 3 | C39: =INDEX(Inputs!$B$21:$E$21,1,2) -> 5 | D39: =$B$13*($C$13+$C$6)*($D$13+$D$6)*($E$18-($E$13+$E$6))*$F$18 -> 427680 | E39: =D39/$B$19 -> 0.0036958686 | F39: =IF(E39>0,1/E39,"-") -> 270.57239 | G39: =C39*E39 -> 0.018479343 | O39: Check vs final RTP | R39: =R38-P20 -> 0
A40: A | B40: 4 | C40: =INDEX(Inputs!$B$21:$E$21,1,3) -> 25 | D40: =$B$13*($C$13+$C$6)*($D$13+$D$6)*($E$13+$E$6)*($F$18-($F$13+$F$6)) -> 102060 | E40: =D40/$B$19 -> 0.00088196864 | F40: =IF(E40>0,1/E40,"-") -> 1133.8272 | G40: =C40*E40 -> 0.022049216
A41: A | B41: 5 | C41: =INDEX(Inputs!$B$21:$E$21,1,4) -> 100 | D41: =$B$13*($C$13+$C$6)*($D$13+$D$6)*($E$13+$E$6)*($F$13+$F$6) -> 14580 | E41: =D41/$B$19 -> 0.00012599552 | F41: =IF(E41>0,1/E41,"-") -> 7936.7901 | G41: =C41*E41 -> 0.012599552
...

Sheet Compliance
A1: Compliance checks
A3: Jurisdiction | B3: Min RTP | C3: Max RTP | D3: Source | E3: 96% variant | F3: 94% variant | G3: 92% variant
A4: Nevada (NGC Reg. 14.040) | B4: 0.75 | C4: - | D4: Nevada Gaming Commission Regulation 14.040: >= 75% of amounts wagered | E4: =IF(AND(PAR_96!P20>=$B4,NOT(AND(ISNUMBER($C4),PAR_96!P20>$C4))),"PASS ("&TEXT(PAR_96!P20,"0.00%")&")","FAIL") -> PASS (96.00%) | F4: =IF(AND(PAR_94!P20>=$B4,NOT(AND(ISNUMBER($C4),PAR_94!P20>$C4))),"PASS ("&TEXT(PAR_94!P20,"0.00%")&")","FAIL") -> PASS (94.00%) | G4: =IF(AND(PAR_92!P20>=$B4,NOT(AND(ISNUMBER($C4),PAR_92!P20>$C4))),"PASS ("&TEXT(PAR_92!P20,"0.00%")&")","FAIL") -> PASS (92.00%)
A5: Mississippi (13 Miss. Code R. 7-12.5) | B5: 0.8 | C5: 1 | D5: 80%-100% for each wager available | E5: =IF(AND(PAR_96!P20>=$B5,NOT(AND(ISNUMBER($C5),PAR_96!P20>$C5))),"PASS ("&TEXT(PAR_96!P20,"0.00%")&")","FAIL") -> PASS (96.00%) | F5: =IF(AND(PAR_94!P20>=$B5,NOT(AND(ISNUMBER($C5),PAR_94!P20>$C5))),"PASS ("&TEXT(PAR_94!P20,"0.00%")&")","FAIL") -> PASS (94.00%) | G5: =IF(AND(PAR_92!P20>=$B5,NOT(AND(ISNUMBER($C5),PAR_92!P20>$C5))),"PASS ("&TEXT(PAR_92!P20,"0.00%")&")","FAIL") -> PASS (92.00%)
A6: New Jersey (N.J.A.C. 13:69E-1.28A) | B6: 0.83 | C6: - | D6: >= 83%; no play with odds > 100 million to 1 | E6: =IF(AND(PAR_96!P20>=$B6,NOT(AND(ISNUMBER($C6),PAR_96!P20>$C6))),"PASS ("&TEXT(PAR_96!P20,"0.00%")&")","FAIL") -> PASS (96.00%) | F6: =IF(AND(PAR_94!P20>=$B6,NOT(AND(ISNUMBER($C6),PAR_94!P20>$C6))),"PASS ("&TEXT(PAR_94!P20,"0.00%")&")","FAIL") -> PASS (94.00%) | G6: =IF(AND(PAR_92!P20>=$B6,NOT(AND(ISNUMBER($C6),PAR_92!P20>$C6))),"PASS ("&TEXT(PAR_92!P20,"0.00%")&")","FAIL") -> PASS (92.00%)
A7: Pennsylvania (4 Pa.C.S. 1207(10)) | B7: 0.85 | C7: - | D7: theoretical payout no less than 85% | E7: =IF(AND(PAR_96!P20>=$B7,NOT(AND(ISNUMBER($C7),PAR_96!P20>$C7))),"PASS ("&TEXT(PAR_96!P20,"0.00%")&")","FAIL") -> PASS (96.00%) | F7: =IF(AND(PAR_94!P20>=$B7,NOT(AND(ISNUMBER($C7),PAR_94!P20>$C7))),"PASS ("&TEXT(PAR_94!P20,"0.00%")&")","FAIL") -> PASS (94.00%) | G7: =IF(AND(PAR_92!P20>=$B7,NOT(AND(ISNUMBER($C7),PAR_92!P20>$C7))),"PASS ("&TEXT(PAR_92!P20,"0.00%")&")","FAIL") -> PASS (92.00%)
A10: Max-win cap and top-award odds
A11: Check | B11: Limit | D11: Basis | E11: 96% variant | F11: 94% variant | G11: 92% variant
A12: Round win never exceeds cap (x bet) | B12: =Inputs!$B$12 -> 5000 | D12: Enforced in game logic; max simulated round win shown | E12: =IF(762.2<=$B12,"PASS (max seen "&TEXT(762.2,"#,##0.0")&"x)","FAIL") -> PASS (max seen 762.2x) | F12: =IF(635.15<=$B12,"PASS (max seen "&TEXT(635.15,"#,##0.0")&"x)","FAIL") -> PASS (max seen 635.2x) | G12: =IF(709.7<=$B12,"PASS (max seen "&TEXT(709.7,"#,##0.0")&"x)","FAIL") -> PASS (max seen 709.7x)
A13: Rarest pay-table line combo odds (1 in, per line) | B13: 100000000 | D13: NJ: no play with odds > 100M:1 (per-line odds are a conservative bound) | E13: =IF(1/MIN(PAR_96!$E$23:$E$53)<=$B13,"PASS (1 in "&TEXT(1/MIN(PAR_96!$E$23:$E$53),"#,##0")&")","FAIL") -> PASS (1 in 470,400) | F13: =IF(1/MIN(PAR_94!$E$23:$E$53)<=$B13,"PASS (1 in "&TEXT(1/MIN(PAR_94!$E$23:$E$53),"#,##0")&")","FAIL") -> PASS (1 in 459,200) | G13: =IF(1/MIN(PAR_92!$E$23:$E$53)<=$B13,"PASS (1 in "&TEXT(1/MIN(PAR_92!$E$23:$E$53),"#,##0")&")","FAIL") -> PASS (1 in 459,200)
A14: Feature trigger reachable on every wager | D14: P(trigger) > 0 from strip counts | E14: =IF(PAR_96!$E$103>0,"PASS","FAIL") -> PASS | F14: =IF(PAR_94!$E$103>0,"PASS","FAIL") -> PASS | G14: =IF(PAR_92!$E$103>0,"PASS","FAIL") -> PASS
A15: P(round reaches 5,000x cap) | D15: Exact (Python DP). Cap is a safety limit, not an advertised pay-table award. | E15: 1.2061556e-45 | F15: 1.2252066e-45 | G15: 1.2197707e-45
A18: RNG / implementation chi-square tests (Python; alpha = 0.01 per test)
A19: Test | B19: Variant | C19: Chi-square | D19: df | E19: p-value | F19: Result
A20: stop uniformity base reel1 | B20: 96% | C20: 20.408411 | D20: 39 | E20: 0.99383607 | F20: =IF(E20>=0.01,"PASS","FAIL") -> PASS
A21: stop uniformity fs reel1 | B21: 96% | C21: 27.611426 | D21: 33 | E21: 0.73234774 | F21: =IF(E21>=0.01,"PASS","FAIL") -> PASS
A22: stop uniformity base reel2 | B22: 96% | C22: 48.805129 | D22: 41 | E22: 0.18802036 | F22: =IF(E22>=0.01,"PASS","FAIL") -> PASS
A23: stop uniformity fs reel2 | B23: 96% | C23: 22.227465 | D23: 33 | E23: 0.92240757 | F23: =IF(E23>=0.01,"PASS","FAIL") -> PASS
A24: stop uniformity base reel3 | B24: 96% | C24: 57.64863 | D24: 41 | E24: 0.043877768 | F24: =IF(E24>=0.01,"PASS","FAIL") -> PASS
A25: stop uniformity fs reel3 | B25: 96% | C25: 46.991778 | D25: 33 | E25: 0.054224165 | F25: =IF(E25>=0.01,"PASS","FAIL") -> PASS
A26: stop uniformity base reel4 | B26: 96% | C26: 31.090977 | D26: 41 | E26: 0.86909295 | F26: =IF(E26>=0.01,"PASS","FAIL") -> PASS
A27: stop uniformity fs reel4 | B27: 96% | C27: 40.879784 | D27: 33 | E27: 0.16289302 | F27: =IF(E27>=0.01,"PASS","FAIL") -> PASS
A28: stop uniformity base reel5 | B28: 96% | C28: 30.260894 | D28: 39 | E28: 0.84081475 | F28: =IF(E28>=0.01,"PASS","FAIL") -> PASS
A29: stop uniformity fs reel5 | B29: 96% | C29: 24.419266 | D29: 33 | E29: 0.86008075 | F29: =IF(E29>=0.01,"PASS","FAIL") -> PASS
A30: independence reel1 x reel2 | B30: 96% | C30: 1698.4166 | D30: 1679 | E30: 0.36494267 | F30: =IF(E30>=0.01,"PASS","FAIL") -> PASS
A31: serial pairs reel1 | B31: 96% | C31: 1565.8072 | D31: 1599 | E31: 0.71879206 | F31: =IF(E31>=0.01,"PASS","FAIL") -> PASS
... A62: raw byte uniformity | B62: raw PCG64 stream | C62: 227.43674 | D62: 255 | E62: 0.89208568 | F62: =IF(E62>=0.01,"PASS","FAIL") -> PASS
A63: raw monobit | B63: raw PCG64 stream | C63: -0.53991124 | D63: z | E63: 0.58925824 | F63: =IF(E63>=0.01,"PASS","FAIL") -> PASS
A64: raw nibble serial pairs | B64: raw PCG64 stream | C64: 271.77524 | D64: 255 | E64: 0.22467574 | F64: =IF(E64>=0.01,"PASS","FAIL") -> PASS
A66: With this many independent tests, about 1% are expected to fall below 0.01 by chance alone.
